# 🔴 오류 분석 보고서

## 🚨 오류 개요
- **발생 시간**: 2025-07-14 06:14:05
- **태스크 ID**: 7490a912-9207-4329-84a7-8d9d0959e118
- **오류 수**: 2개
- **심각도**: 중간 (기능은 작동하나 개선 필요)

## 📍 오류 상세

### 오류 1: git_add() 에러 메시지 누락
- **위치**: python/ai_helpers/git_enhanced.py
- **함수**: git_add()
- **현상**: 실패 시 error 필드가 None으로 반환
- **재현**: 
  ```python
  add_result = helpers.git_add('test_git_helpers/test_file_0.txt')
  # 반환: HelperResult(ok=False, data={}, error=None)  # error가 None!
  ```
- **영향**: 디버깅 어려움, 사용자가 실패 원인을 알 수 없음

### 오류 2: stderr 출력 처리 미흡
- **위치**: 테스트 실행 중
- **현상**: "FileNotFoundError: [WinError 2] 지정된 파일을 찾을 수 없습니다"
- **원인**: subprocess 실행 실패 시 stderr 캡처 누락
- **영향**: 예외 발생 시 적절한 에러 처리 안됨

## 💡 해결 방안

### 즉각적인 수정
```python
# 수정 전 (git_enhanced.py)
def git_add(file_path):
    result = _git_enhancer._run_git_command(['add', file_path])
    if result['success']:
        return HelperResult(True, {'file_path': file_path})
    else:
        return HelperResult(False, None)  # 문제: error 메시지 없음

# 수정 후
def git_add(file_path):
    result = _git_enhancer._run_git_command(['add', file_path])
    if result['success']:
        return HelperResult(True, {'file_path': file_path})
    else:
        error_msg = result.get('error', 'Git add failed')
        return HelperResult(False, error_msg)  # 개선: 에러 메시지 포함
```

## 📊 모듈 수정 사항
- **수정된 모듈**: 없음 (테스트만 수행, 실제 수정은 미적용)
- **수정 필요 모듈**: python/ai_helpers/git_enhanced.py

## ✅ 검증 필요 사항
- [ ] git_add() 에러 메시지 수정 후 재테스트
- [ ] 다른 git 함수들의 에러 처리 일관성 검토
- [ ] stderr 캡처 로직 개선
